2023-03-11 08:35:23,477 INFO    Thread-28 (_run_job):44681 [wandb_setup.py:_flush():76] Configure stats pid to 44681
2023-03-11 08:35:23,477 INFO    Thread-28 (_run_job):44681 [wandb_setup.py:_flush():76] Loading settings from /Users/crysiswar999/.config/wandb/settings
2023-03-11 08:35:23,477 INFO    Thread-28 (_run_job):44681 [wandb_setup.py:_flush():76] Loading settings from /Users/crysiswar999/Documents/GitHub/CS6910-Assignment-1/wandb/settings
2023-03-11 08:35:23,477 INFO    Thread-28 (_run_job):44681 [wandb_setup.py:_flush():76] Loading settings from environment variables: {'project': 'CS6910_DL_assignment_1', 'entity': 'cs22m031', 'root_dir': '/Users/crysiswar999/Documents/GitHub/CS6910-Assignment-1', 'run_id': 'hvqhnwfz', 'sweep_param_path': '/Users/crysiswar999/Documents/GitHub/CS6910-Assignment-1/wandb/sweep-naxh06ik/config-hvqhnwfz.yaml', 'sweep_id': 'naxh06ik'}
2023-03-11 08:35:23,477 INFO    Thread-28 (_run_job):44681 [wandb_setup.py:_flush():76] Applying setup settings: {'_disable_service': False}
2023-03-11 08:35:23,477 INFO    Thread-28 (_run_job):44681 [wandb_setup.py:_flush():76] Inferring run settings from compute environment: {'program': '<python with no main file>'}
2023-03-11 08:35:23,477 INFO    Thread-28 (_run_job):44681 [wandb_init.py:_log_setup():506] Logging user logs to /Users/crysiswar999/Documents/GitHub/CS6910-Assignment-1/wandb/run-20230311_083523-hvqhnwfz/logs/debug.log
2023-03-11 08:35:23,477 INFO    Thread-28 (_run_job):44681 [wandb_init.py:_log_setup():507] Logging internal logs to /Users/crysiswar999/Documents/GitHub/CS6910-Assignment-1/wandb/run-20230311_083523-hvqhnwfz/logs/debug-internal.log
2023-03-11 08:35:23,477 INFO    Thread-28 (_run_job):44681 [wandb_init.py:_jupyter_setup():452] configuring jupyter hooks <wandb.sdk.wandb_init._WandbInit object at 0x159fd9660>
2023-03-11 08:35:23,477 INFO    Thread-28 (_run_job):44681 [wandb_init.py:init():546] calling init triggers
2023-03-11 08:35:23,477 INFO    Thread-28 (_run_job):44681 [wandb_init.py:init():552] wandb.init called with sweep_config: {'activation': 'relu', 'batchsize': 128, 'eta': 0.002, 'initialization': 'he', 'loss': 'cross', 'max_epochs': 15, 'no_of_classes': 10, 'no_of_features': 784, 'no_of_layers': 5, 'no_of_neurons': 512, 'optimizer': 'nadam', 'weight_decay': 0.001}
config: {}
2023-03-11 08:35:23,477 INFO    Thread-28 (_run_job):44681 [wandb_init.py:init():602] starting backend
2023-03-11 08:35:23,477 INFO    Thread-28 (_run_job):44681 [wandb_init.py:init():606] setting up manager
2023-03-11 08:35:23,483 INFO    Thread-28 (_run_job):44681 [backend.py:_multiprocessing_setup():106] multiprocessing start_methods=spawn,fork,forkserver, using: spawn
2023-03-11 08:35:23,486 INFO    Thread-28 (_run_job):44681 [wandb_init.py:init():613] backend started and connected
2023-03-11 08:35:23,490 INFO    Thread-28 (_run_job):44681 [wandb_run.py:_config_callback():1249] config_cb None None {'activation': 'relu', 'batchsize': 128, 'eta': 0.002, 'initialization': 'he', 'loss': 'cross', 'max_epochs': 15, 'no_of_classes': 10, 'no_of_features': 784, 'no_of_layers': 5, 'no_of_neurons': 512, 'optimizer': 'nadam', 'weight_decay': 0.001}
2023-03-11 08:35:23,518 INFO    Thread-28 (_run_job):44681 [wandb_run.py:_label_probe_notebook():1202] probe notebook
2023-03-11 08:35:23,518 INFO    Thread-28 (_run_job):44681 [wandb_run.py:_label_probe_notebook():1212] Unable to probe notebook: 'NoneType' object has no attribute 'get'
2023-03-11 08:35:23,518 INFO    Thread-28 (_run_job):44681 [wandb_init.py:init():701] updated telemetry
2023-03-11 08:35:23,539 INFO    Thread-28 (_run_job):44681 [wandb_init.py:init():741] communicating run to backend with 60.0 second timeout
2023-03-11 08:35:24,285 INFO    Thread-28 (_run_job):44681 [wandb_run.py:_on_init():2131] communicating current version
2023-03-11 08:35:24,342 INFO    Thread-28 (_run_job):44681 [wandb_run.py:_on_init():2140] got version response 
2023-03-11 08:35:24,342 INFO    Thread-28 (_run_job):44681 [wandb_init.py:init():789] starting run threads in backend
2023-03-11 08:35:24,406 INFO    Thread-28 (_run_job):44681 [wandb_run.py:_console_start():2112] atexit reg
2023-03-11 08:35:24,406 INFO    Thread-28 (_run_job):44681 [wandb_run.py:_redirect():1967] redirect: SettingsConsole.WRAP_RAW
2023-03-11 08:35:24,406 INFO    Thread-28 (_run_job):44681 [wandb_run.py:_redirect():2032] Wrapping output streams.
2023-03-11 08:35:24,406 INFO    Thread-28 (_run_job):44681 [wandb_run.py:_redirect():2057] Redirects installed.
2023-03-11 08:35:24,407 INFO    Thread-28 (_run_job):44681 [wandb_init.py:init():831] run started, returning control to user process
2023-03-11 09:15:01,416 INFO    Thread-5 (_heartbeat):44681 [retry.py:__call__():172] Retry attempt failed:
Traceback (most recent call last):
  File "/opt/homebrew/lib/python3.10/site-packages/urllib3/connection.py", line 174, in _new_conn
    conn = connection.create_connection(
  File "/opt/homebrew/lib/python3.10/site-packages/urllib3/util/connection.py", line 72, in create_connection
    for res in socket.getaddrinfo(host, port, family, socket.SOCK_STREAM):
  File "/opt/homebrew/Cellar/python@3.10/3.10.6_2/Frameworks/Python.framework/Versions/3.10/lib/python3.10/socket.py", line 955, in getaddrinfo
    for res in _socket.getaddrinfo(host, port, family, type, proto, flags):
socket.gaierror: [Errno 8] nodename nor servname provided, or not known

During handling of the above exception, another exception occurred:

Traceback (most recent call last):
  File "/opt/homebrew/lib/python3.10/site-packages/urllib3/connectionpool.py", line 703, in urlopen
    httplib_response = self._make_request(
  File "/opt/homebrew/lib/python3.10/site-packages/urllib3/connectionpool.py", line 386, in _make_request
    self._validate_conn(conn)
  File "/opt/homebrew/lib/python3.10/site-packages/urllib3/connectionpool.py", line 1042, in _validate_conn
    conn.connect()
  File "/opt/homebrew/lib/python3.10/site-packages/urllib3/connection.py", line 358, in connect
    self.sock = conn = self._new_conn()
  File "/opt/homebrew/lib/python3.10/site-packages/urllib3/connection.py", line 186, in _new_conn
    raise NewConnectionError(
urllib3.exceptions.NewConnectionError: <urllib3.connection.HTTPSConnection object at 0x15feea8c0>: Failed to establish a new connection: [Errno 8] nodename nor servname provided, or not known

During handling of the above exception, another exception occurred:

Traceback (most recent call last):
  File "/opt/homebrew/lib/python3.10/site-packages/requests/adapters.py", line 489, in send
    resp = conn.urlopen(
  File "/opt/homebrew/lib/python3.10/site-packages/urllib3/connectionpool.py", line 787, in urlopen
    retries = retries.increment(
  File "/opt/homebrew/lib/python3.10/site-packages/urllib3/util/retry.py", line 592, in increment
    raise MaxRetryError(_pool, url, error or ResponseError(cause))
urllib3.exceptions.MaxRetryError: HTTPSConnectionPool(host='api.wandb.ai', port=443): Max retries exceeded with url: /graphql (Caused by NewConnectionError('<urllib3.connection.HTTPSConnection object at 0x15feea8c0>: Failed to establish a new connection: [Errno 8] nodename nor servname provided, or not known'))

During handling of the above exception, another exception occurred:

Traceback (most recent call last):
  File "/opt/homebrew/lib/python3.10/site-packages/wandb/sdk/lib/retry.py", line 131, in __call__
    result = self._call_fn(*args, **kwargs)
  File "/opt/homebrew/lib/python3.10/site-packages/wandb/sdk/internal/internal_api.py", line 242, in execute
    return self.client.execute(*args, **kwargs)  # type: ignore
  File "/opt/homebrew/lib/python3.10/site-packages/wandb/vendor/gql-0.2.0/wandb_gql/client.py", line 52, in execute
    result = self._get_result(document, *args, **kwargs)
  File "/opt/homebrew/lib/python3.10/site-packages/wandb/vendor/gql-0.2.0/wandb_gql/client.py", line 60, in _get_result
    return self.transport.execute(document, *args, **kwargs)
  File "/opt/homebrew/lib/python3.10/site-packages/wandb/vendor/gql-0.2.0/wandb_gql/transport/requests.py", line 38, in execute
    request = requests.post(self.url, **post_args)
  File "/opt/homebrew/lib/python3.10/site-packages/requests/api.py", line 115, in post
    return request("post", url, data=data, json=json, **kwargs)
  File "/opt/homebrew/lib/python3.10/site-packages/requests/api.py", line 59, in request
    return session.request(method=method, url=url, **kwargs)
  File "/opt/homebrew/lib/python3.10/site-packages/requests/sessions.py", line 587, in request
    resp = self.send(prep, **send_kwargs)
  File "/opt/homebrew/lib/python3.10/site-packages/requests/sessions.py", line 701, in send
    r = adapter.send(request, **kwargs)
  File "/opt/homebrew/lib/python3.10/site-packages/requests/adapters.py", line 565, in send
    raise ConnectionError(e, request=request)
requests.exceptions.ConnectionError: HTTPSConnectionPool(host='api.wandb.ai', port=443): Max retries exceeded with url: /graphql (Caused by NewConnectionError('<urllib3.connection.HTTPSConnection object at 0x15feea8c0>: Failed to establish a new connection: [Errno 8] nodename nor servname provided, or not known'))
2023-03-11 09:48:32,549 INFO    Thread-28 (_run_job):44681 [wandb_run.py:_finish():1852] finishing run cs22m031/CS6910_DL_assignment_1/hvqhnwfz
2023-03-11 09:48:32,552 INFO    Thread-28 (_run_job):44681 [jupyter.py:save_history():445] not saving jupyter history
2023-03-11 09:48:32,552 INFO    Thread-28 (_run_job):44681 [jupyter.py:save_ipynb():373] not saving jupyter notebook
2023-03-11 09:48:32,552 INFO    Thread-28 (_run_job):44681 [wandb_init.py:_jupyter_teardown():434] cleaning up jupyter logic
2023-03-11 09:48:32,552 INFO    Thread-28 (_run_job):44681 [wandb_run.py:_atexit_cleanup():2081] got exitcode: 0
2023-03-11 09:48:32,553 INFO    Thread-28 (_run_job):44681 [wandb_run.py:_restore():2064] restore
2023-03-11 09:48:32,554 INFO    Thread-28 (_run_job):44681 [wandb_run.py:_restore():2070] restore done
2023-03-11 09:48:57,188 INFO    Thread-28 (_run_job):44681 [wandb_run.py:_footer_history_summary_info():3429] rendering history
2023-03-11 09:48:57,189 INFO    Thread-28 (_run_job):44681 [wandb_run.py:_footer_history_summary_info():3461] rendering summary
2023-03-11 09:48:57,209 INFO    Thread-28 (_run_job):44681 [wandb_run.py:_footer_sync_info():3387] logging synced files
